Workbook

Sheet planilha crua
A1: id | B1: data | C1: quinz | D1: coleta | E1: hora coleta | F1: hora freezer | G1: tempo de manipulacao | H1: sexo | I1: posicao | J1: trilha | K1: idteia | L1: situacao da teia | M1: agreg | N1: parasita | O1: establimento | P1: estagio da femea | Q1: id foto | R1: comprimento corpo | S1: comprimento perna e | T1: comprimento perna d | U1: largura cefalotorax | V1: largura do abdomen | W1: observacoes | X1: obs2 | Y1: obs3
A2: f01 | B2: 45401 | C2: =INT((DATE(2000, MONTH(B2), DAY(B2)) - DATE(2000, 3, 12)) / 15) + 1 -> 3 | D2: 1 | E2: 0.58333333 | F2: 17:30-18:50 | H2: f | I2: na | J2: 1 | K2: 1 | L2: s | M2: na | N2: 0 | O2: 0 | P2: madura | Q2: 5580-5581 | R2: 2.679 | S2: 5.449 | T2: 5.518 | U2: 0.593 | V2: 0.781 | X2: Pouco gelo, caixa de isopor quente
A3: m01 | B3: 45401 | C3: =INT((DATE(2000, MONTH(B3), DAY(B3)) - DATE(2000, 3, 12)) / 15) + 1 -> 3 | D3: 1 | E3: 0.58333333 | F3: 17:30-18:50 | H3: m | I3: c | J3: 1 | K3: 1 | L3: s | M3: na | N3: 0 | O3: 0 | P3: na | Q3: 5640 | R3: 0.524 | S3: 1.633 | T3: 1.636 | U3: 0.145 | V3: 0.121 | W3: Estava na lateral da teia, mas estava se alimentando | X3: Pouco gelo, caixa de isopor quente
A4: f02 | B4: 45401 | C4: =INT((DATE(2000, MONTH(B4), DAY(B4)) - DATE(2000, 3, 12)) / 15) + 1 -> 3 | D4: 1 | E4: 0.58333333 | F4: 17:30-18:50 | H4: f | I4: na | J4: 1 | K4: 2 | L4: s | M4: na | N4: 0 | O4: 0 | P4: madura | Q4: 5574-5575 | R4: 2.291 | S4: na | T4: 5.65 | U4: 0.606 | V4: 0.498 | X4: Pouco gelo, caixa de isopor quente
A5: m02 | B5: 45401 | C5: =INT((DATE(2000, MONTH(B5), DAY(B5)) - DATE(2000, 3, 12)) / 15) + 1 -> 3 | D5: 1 | E5: 0.58333333 | F5: 17:30-18:50 | H5: m | I5: c | J5: 1 | K5: 3 | L5: a | M5: 1 | N5: 0 | O5: 0 | P5: na | Q5: 5638-5639 | R5: 0.591 | S5: 1.579 | T5: 1.824 | U5: 0.177 | V5: 0.112 | X5: Pouco gelo, caixa de isopor quente
A6: f03 | B6: 45401 | C6: =INT((DATE(2000, MONTH(B6), DAY(B6)) - DATE(2000, 3, 12)) / 15) + 1 -> 3 | D6: 1 | E6: 0.59027778 | F6: 17:30-18:50 | H6: f | I6: na | J6: 1 | K6: 3 | L6: a | M6: 1 | N6: 0 | O6: 0 | P6: madura | Q6: 5570-5571 | R6: 1.992 | S6: 5.005 | T6: 4.844 | U6: 0.493 | V6: 0.466 | X6: Pouco gelo, caixa de isopor quente
A7: f04 | B7: 45401 | C7: =INT((DATE(2000, MONTH(B7), DAY(B7)) - DATE(2000, 3, 12)) / 15) + 1 -> 3 | D7: 1 | E7: 0.59027778 | F7: 17:30-18:50 | H7: f | I7: na | J7: 1 | K7: 4 | L7: a | M7: 1 | N7: 0 | O7: 0 | P7: madura | Q7: 5468-5511 | R7: 2.078 | S7: na | T7: 4.665 | U7: 0.517 | V7: 0.55 | X7: Pouco gelo, caixa de isopor quente
A8: f05 | B8: 45401 | C8: =INT((DATE(2000, MONTH(B8), DAY(B8)) - DATE(2000, 3, 12)) / 15) + 1 -> 3 | D8: 1 | E8: 0.59027778 | F8: 17:30-18:50 | H8: f | I8: na | J8: 1 | K8: 5 | L8: a | M8: 1 | N8: 0 | O8: 0 | P8: madura | Q8: 5568-5569 | R8: 2.69 | S8: 5.435 | T8: 5.301 | U8: 0.65 | V8: 0.626 | X8: Pouco gelo, caixa de isopor quente
A9: f06 | B9: 45401 | C9: =INT((DATE(2000, MONTH(B9), DAY(B9)) - DATE(2000, 3, 12)) / 15) + 1 -> 3 | D9: 1 | E9: 0.59027778 | F9: 17:30-18:50 | H9: f | I9: na | J9: 1 | K9: 6 | L9: a | M9: 1 | N9: 0 | O9: 0 | P9: madura | Q9: 5600-5601 | R9: 2.091 | S9: 3.889 | T9: 3.883 | U9: 0.445 | V9: 0.505 | W9: Perdeu a perna durante o manejo | X9: Pouco gelo, caixa de isopor quente
A10: f07 | B10: 45401 | C10: =INT((DATE(2000, MONTH(B10), DAY(B10)) - DATE(2000, 3, 12)) / 15) + 1 -> 3 | D10: 1 | E10: 0.59027778 | F10: 17:30-18:50 | H10: f | I10: na | J10: 1 | K10: 7 | L10: a | M10: 1 | N10: 0 | O10: 2 | P10: madura | Q10: 5611-5612 | R10: 2.293 | S10: na | T10: 5.434 | U10: 0.589 | V10: 0.496 | X10: Pouco gelo, caixa de isopor quente
A11: f08 | B11: 45401 | C11: =INT((DATE(2000, MONTH(B11), DAY(B11)) - DATE(2000, 3, 12)) / 15) + 1 -> 3 | D11: 1 | E11: 0.60208333 | F11: 17:30-18:50 | H11: f | I11: na | J11: 1 | K11: 8 | L11: a | M11: 1 | N11: 0 | O11: 0 | P11: madura | Q11: 5594-5595 | R11: 2.358 | S11: 6.01 | T11: 5.839 | U11: 0.641 | V11: 0.51 | X11: Pouco gelo, caixa de isopor quente
A12: f09 | B12: 45401 | C12: =INT((DATE(2000, MONTH(B12), DAY(B12)) - DATE(2000, 3, 12)) / 15) + 1 -> 3 | D12: 1 | E12: 0.60486111 | F12: 17:30-18:50 | H12: f | I12: na | J12: 1 | K12: 9 | L12: s | M12: na | N12: 0 | O12: 0 | P12: madura | Q12: 5481-5498 | R12: 2.106 | S12: 4.866 | T12: 4.676 | U12: 0.495 | V12: 0.578 | X12: Pouco gelo, caixa de isopor quente | Y12: Trocou de pote
A13: m03 | B13: 45401 | C13: =INT((DATE(2000, MONTH(B13), DAY(B13)) - DATE(2000, 3, 12)) / 15) + 1 -> 3 | D13: 1 | E13: 0.61458333 | F13: 17:30-18:50 | H13: m | I13: c | J13: 1 | K13: 10 | L13: s | M13: na | N13: 0 | O13: 0 | P13: na | Q13: 5641 | R13: 0.557 | S13: na | T13: 1.898 | U13: 0.186 | V13: 0.109 | X13: Pouco gelo, caixa de isopor quente | Y13: sem a perna esquerda
A14: m04 | B14: 45401 | C14: =INT((DATE(2000, MONTH(B14), DAY(B14)) - DATE(2000, 3, 12)) / 15) + 1 -> 3 | D14: 1 | E14: 0.61458333 | F14: 17:30-18:50 | H14: me | I14: P | J14: 1 | K14: 10 | L14: s | M14: na | N14: 0 | O14: 0 | P14: na | Q14: na | R14: na | S14: na | T14: na | U14: na | V14: na | W14: conferir se m ou E (acho que é um ectoparasita) | X14: Pouco gelo, caixa de isopor quente
A15: f10 | B15: 45401 | C15: =INT((DATE(2000, MONTH(B15), DAY(B15)) - DATE(2000, 3, 12)) / 15) + 1 -> 3 | D15: 1 | E15: 0.61458333 | F15: 17:30-18:50 | H15: f | I15: na | J15: 1 | K15: 10 | L15: s | M15: na | N15: 0 | O15: 0 | P15: madura | Q15: 5602-5604 | R15: 2.269 | S15: 4.913 | T15: 5.062 | U15: 0.545 | V15: 0.591 | X15: Pouco gelo, caixa de isopor quente
A16: m05 | B16: 45401 | C16: =INT((DATE(2000, MONTH(B16), DAY(B16)) - DATE(2000, 3, 12)) / 15) + 1 -> 3 | D16: 1 | E16: 0.62222222 | F16: 17:30-18:50 | H16: m | I16: c | J16: 1 | K16: 11 | L16: s | M16: na | N16: 0 | O16: 0 | P16: na | Q16: 5637 | R16: 0.888 | S16: 3.101 | T16: na | U16: 0.234 | V16: 0.17 | X16: Pouco gelo, caixa de isopor quente | Y16: sem perna direita
A17: f11 | B17: 45401 | C17: =INT((DATE(2000, MONTH(B17), DAY(B17)) - DATE(2000, 3, 12)) / 15) + 1 -> 3 | D17: 1 | E17: 0.62222222 | F17: 17:30-18:50 | H17: f | I17: na | J17: 1 | K17: 11 | L17: s | M17: na | N17: 0 | O17: 0 | P17: madura | Q17: 5590-5591 | R17: 2.707 | S17: 5.234 | T17: 4.979 | U17: 0.607 | V17: 0.739 | X17: Pouco gelo, caixa de isopor quente
A18: m06 | B18: 45401 | C18: =INT((DATE(2000, MONTH(B18), DAY(B18)) - DATE(2000, 3, 12)) / 15) + 1 -> 3 | D18: 1 | E18: 0.62708333 | F18: 17:30-18:50 | H18: m | I18: P | J18: 1 | K18: 12 | L18: s | M18: na | N18: 0 | O18: 3 | P18: na | Q18: 5642 | R18: 0.593 | S18: na | T18: na | U18: 0.181 | V18: 0.109 | X18: Pouco gelo, caixa de isopor quente | Y18: duas pernas dianteiras ausentes
A19: f12 | B19: 45401 | C19: =INT((DATE(2000, MONTH(B19), DAY(B19)) - DATE(2000, 3, 12)) / 15) + 1 -> 3 | D19: 1 | E19: 0.62708333 | F19: 17:30-18:50 | H19: f | I19: na | J19: 1 | K19: 12 | L19: s | M19: na | N19: 0 | O19: 3 | P19: madura | Q19: 5598-5599 | R19: 2.747 | S19: 5.198 | T19: 5.162 | U19: 0.579 | V19: 0.714 | W19: se alimentou logo antes da captura | X19: Pouco gelo, caixa de isopor quente
A20: m07 | B20: 45401 | C20: =INT((DATE(2000, MONTH(B20), DAY(B20)) - DATE(2000, 3, 12)) / 15) + 1 -> 3 | D20: 1 | E20: 0.63958333 | F20: 17:30-18:50 | H20: m | I20: c | J20: 1 | K20: 13 | L20: s | M20: na | N20: 0 | O20: 1 | P20: na | Q20: 5643 | R20: 0.659 | S20: 2.403 | T20: na | U20: 0.194 | V20: 0.109 | X20: Pouco gelo, caixa de isopor quente | Y20: sem perna direita
A21: f13 | B21: 45401 | C21: =INT((DATE(2000, MONTH(B21), DAY(B21)) - DATE(2000, 3, 12)) / 15) + 1 -> 3 | D21: 1 | E21: 0.63958333 | F21: 17:30-18:50 | H21: f | I21: na | J21: 1 | K21: 13 | L21: s | M21: na | N21: 0 | O21: 1 | P21: madura | Q21: 5592-5593 | R21: 2.472 | S21: 5.63 | T21: 5.606 | U21: 0.587 | V21: 0.583 | W21: se alimentou logo antes da captura, já havia sido marcada com tinta para outro experimento | X21: Pouco gelo, caixa de isopor quente
A22: f14 | B22: 45401 | C22: =INT((DATE(2000, MONTH(B22), DAY(B22)) - DATE(2000, 3, 12)) / 15) + 1 -> 3 | D22: 1 | E22: 0.65486111 | F22: 17:30-18:50 | H22: f | I22: na | J22: 2 | K22: 14 | L22: s | M22: na | N22: 0 | O22: 1 | P22: madura | Q22: 5512-5513 | R22: 2.471 | S22: na | T22: 4.922 | U22: 0.526 | V22: 0.623 | X22: Pouco gelo, caixa de isopor quente | Y22: Trocou de pote
A23: m08 | B23: 45401 | C23: =INT((DATE(2000, MONTH(B23), DAY(B23)) - DATE(2000, 3, 12)) / 15) + 1 -> 3 | D23: 1 | E23: 0.65486111 | F23: 17:30-18:50 | H23: m | I23: c | J23: 2 | K23: 14 | L23: s | M23: na | N23: 0 | O23: 1 | P23: na | Q23: 5644 | R23: 0.628 | S23: na | T23: 2.066 | U23: 0.183 | V23: 0.115 | X23: Pouco gelo, caixa de isopor quente
A24: f15 | B24: 45401 | C24: =INT((DATE(2000, MONTH(B24), DAY(B24)) - DATE(2000, 3, 12)) / 15) + 1 -> 3 | D24: 1 | E24: 0.65486111 | F24: 17:30-18:50 | H24: f | I24: na | J24: 2 | K24: 15 | L24: s | M24: na | N24: 0 | O24: 0 | P24: madura | Q24: 5518-5519 | R24: 2.69 | S24: 5.11 | T24: 5.25 | U24: 0.554 | V24: 0.654 | W24: Já havia sido marcada com tinta parra outro experimento | X24: Pouco gelo, caixa de isopor quente | Y24: Trocou de pote
A25: f16 | B25: 45401 | C25: =INT((DATE(2000, MONTH(B25), DAY(B25)) - DATE(2000, 3, 12)) / 15) + 1 -> 3 | D25: 1 | E25: 0.66180556 | F25: 17:30-18:50 | H25: f | I25: na | J25: 2 | K25: 16 | L25: s | M25: na | N25: 0 | O25: 1 | P25: madura | Q25: 5566-5567 | R25: 2.456 | S25: 4.423 | T25: 4.826 | U25: 0.532 | V25: 0.604 | X25: Pouco gelo, caixa de isopor quente
A26: f17 | B26: 45401 | C26: =INT((DATE(2000, MONTH(B26), DAY(B26)) - DATE(2000, 3, 12)) / 15) + 1 -> 3 | D26: 1 | E26: 0.69583333 | F26: 17:30-18:50 | H26: f | I26: na | J26: 3 | K26: 17 | L26: a | M26: 2 | N26: 0 | O26: 0 | P26: madura | Q26: 5514-5515 | R26: 2.33 | S26: 5.051 | T26: 5.009 | U26: 0.484 | V26: 0.537 | X26: Pouco gelo, caixa de isopor quente | Y26: Trocou de pote
A27: f18 | B27: 45401 | C27: =INT((DATE(2000, MONTH(B27), DAY(B27)) - DATE(2000, 3, 12)) / 15) + 1 -> 3 | D27: 1 | E27: 0.69583333 | F27: 17:30-18:50 | H27: f | I27: na | J27: 3 | K27: 18 | L27: a | M27: 2 | N27: 0 | O27: 0 | P27: madura | Q27: 5625-5626 | R27: 1.941 | S27: 3.822 | T27: 3.79 | U27: 0.386 | V27: 0.498 | X27: Pouco gelo, caixa de isopor quente
A28: m09 | B28: 45401 | C28: =INT((DATE(2000, MONTH(B28), DAY(B28)) - DATE(2000, 3, 12)) / 15) + 1 -> 3 | D28: 1 | E28: 0.69583333 | F28: 17:30-18:50 | H28: m | I28: c | J28: 3 | K28: 19 | L28: a | M28: 2 | N28: 0 | O28: 0 | P28: na | Q28: 5636 | R28: 0.899 | S28: na | T28: 3.397 | U28: 0.26 | V28: 0.177 | X28: Pouco gelo, caixa de isopor quente | Y28: sem a perna esquerda
A29: f19 | B29: 45401 | C29: =INT((DATE(2000, MONTH(B29), DAY(B29)) - DATE(2000, 3, 12)) / 15) + 1 -> 3 | D29: 1 | E29: 0.69583333 | F29: 17:30-18:50 | H29: f | I29: na | J29: 3 | K29: 19 | L29: a | M29: 2 | N29: 0 | O29: 0 | P29: madura | Q29: 5623-5624 | R29: 2.785 | S29: 5.339 | T29: 5.38 | U29: 0.559 | V29: 0.729 | X29: Pouco gelo, caixa de isopor quente
A30: m10 | B30: 45401 | C30: =INT((DATE(2000, MONTH(B30), DAY(B30)) - DATE(2000, 3, 12)) / 15) + 1 -> 3 | D30: 1 | E30: 0.69583333 | F30: 17:30-18:50 | H30: m | I30: c | J30: 3 | K30: 20 | L30: a | M30: 2 | N30: 0 | O30: 0 | P30: na | Q30: 5645 | R30: 0.541 | S30: 1.945 | T30: na | U30: 0.145 | V30: 0.106 | X30: Pouco gelo, caixa de isopor quente | Y30: sem perna direita
A31: f20 | B31: 45401 | C31: =INT((DATE(2000, MONTH(B31), DAY(B31)) - DATE(2000, 3, 12)) / 15) + 1 -> 3 | D31: 1 | E31: 0.69583333 | F31: 17:30-18:50 | H31: f | I31: na | J31: 3 | K31: 20 | L31: a | M31: 2 | N31: 0 | O31: 0 | P31: madura | Q31: 5605-5606 | R31: 2.409 | S31: 5.147 | T31: 5.282 | U31: 0.579 | V31: 0.488 | X31: Pouco gelo, caixa de isopor quente
A32: f21 | B32: 45401 | C32: =INT((DATE(2000, MONTH(B32), DAY(B32)) - DATE(2000, 3, 12)) / 15) + 1 -> 3 | D32: 1 | E32: 0.69583333 | F32: 17:30-18:50 | H32: f | I32: na | J32: 3 | K32: 21 | L32: a | M32: 2 | N32: 0 | O32: 0 | P32: madura | Q32: 5613-5614 | R32: 2.436 | S32: 4.675 | T32: 4.68 | U32: 0.495 | V32: 0.639 | X32: Pouco gelo, caixa de isopor quente
A33: f22 | B33: 45401 | C33: =INT((DATE(2000, MONTH(B33), DAY(B33)) - DATE(2000, 3, 12)) / 15) + 1 -> 3 | D33: 1 | E33: 0.69583333 | F33: 17:30-18:50 | H33: f | I33: na | J33: 3 | K33: 22 | L33: a | M33: 2 | N33: 0 | O33: 0 | P33: madura | Q33: 5546-5547 | R33: 2.357 | S33: 4.461 | T33: 4.334 | U33: 0.502 | V33: 0.512 | W33: Asterisco: a posição pode ter trocado com a f23 durante a coleta | X33: Pouco gelo, caixa de isopor quente | Y33: Trocou de pote
A34: f23 | B34: 45401 | C34: =INT((DATE(2000, MONTH(B34), DAY(B34)) - DATE(2000, 3, 12)) / 15) + 1 -> 3 | D34: 1 | E34: 0.69583333 | F34: 17:30-18:50 | H34: f | I34: na | J34: 3 | K34: 23 | L34: a | M34: 2 | N34: 0 | O34: 0 | P34: madura | Q34: 5615-5616 | R34: 2.828 | S34: 5.639 | T34: 5.672 | U34: 0.588 | V34: 0.839 | W34: Asterisco: a posição pode ter trocado com a f22 durante a coleta | X34: Pouco gelo, caixa de isopor quente
A35: f24 | B35: 45401 | C35: =INT((DATE(2000, MONTH(B35), DAY(B35)) - DATE(2000, 3, 12)) / 15) + 1 -> 3 | D35: 1 | E35: 0.69583333 | F35: 17:30-18:50 | H35: f | I35: na | J35: 3 | K35: 24 | L35: a | M35: 2 | N35: 0 | O35: 0 | P35: madura | Q35: 5537-5538 | R35: 2.179 | S35: na | T35: 4.639 | U35: 0.513 | V35: 0.425 | X35: Pouco gelo, caixa de isopor quente
A36: f25 | B36: 45401 | C36: =INT((DATE(2000, MONTH(B36), DAY(B36)) - DATE(2000, 3, 12)) / 15) + 1 -> 3 | D36: 1 | E36: 0.71527778 | F36: 17:30-18:50 | H36: f | I36: na | J36: 3 | K36: 25 | L36: a | M36: 2 | N36: 0 | O36: 0 | P36: madura | Q36: 5617-5618 | R36: 2.693 | S36: 5.797 | T36: na | U36: 0.585 | V36: 0.551 | X36: Pouco gelo, caixa de isopor quente
A37: f26 | B37: 45401 | C37: =INT((DATE(2000, MONTH(B37), DAY(B37)) - DATE(2000, 3, 12)) / 15) + 1 -> 3 | D37: 1 | E37: 0.71527778 | F37: 17:30-18:50 | H37: f | I37: na | J37: 3 | K37: 26 | L37: a | M37: 2 | N37: 0 | O37: 0 | P37: madura | Q37: 5621-5622 | R37: 2.393 | S37: 4.713 | T37: 4.65 | U37: 0.479 | V37: 0.609 | X37: Pouco gelo, caixa de isopor quente
A38: f27 | B38: 45401 | C38: =INT((DATE(2000, MONTH(B38), DAY(B38)) - DATE(2000, 3, 12)) / 15) + 1 -> 3 | D38: 1 | E38: 0.71527778 | F38: 17:30-18:50 | H38: f | I38: na | J38: 3 | K38: 27 | L38: a | M38: 2 | N38: 0 | O38: 0 | P38: madura | Q38: 5480-5496 | R38: 2.462 | S38: 5.566 | T38: 5.424 | U38: 0.591 | V38: 0.583 | X38: Pouco gelo, caixa de isopor quente | Y38: Trocou de pote
A39: f28 | B39: 45401 | C39: =INT((DATE(2000, MONTH(B39), DAY(B39)) - DATE(2000, 3, 12)) / 15) + 1 -> 3 | D39: 1 | E39: 0.71527778 | F39: 17:30-18:50 | H39: f | I39: na | J39: 3 | K39: 28 | L39: a | M39: 2 | N39: 0 | O39: 0 | P39: madura | Q39: 5596-5597 | R39: 2.218 | S39: 4.043 | T39: 4.57 | U39: 0.492 | V39: 0.553 | X39: Pouco gelo, caixa de isopor quente
A40: f29 | B40: 45401 | C40: =INT((DATE(2000, MONTH(B40), DAY(B40)) - DATE(2000, 3, 12)) / 15) + 1 -> 3 | D40: 1 | E40: 0.71527778 | F40: 17:30-18:50 | H40: f | I40: na | J40: 3 | K40: 29 | L40: a | M40: 2 | N40: 0 | O40: 0 | P40: madura | Q40: 5607-5608 | R40: 2.251 | S40: 4.719 | T40: 4.719 | U40: 0.464 | V40: 0.567 | X40: Pouco gelo, caixa de isopor quente
...

Sheet Sem os errados
A1: id | B1: coleta | C1: sexo | D1: posicao | E1: trilha | F1: idteia | G1: situacao da teia | H1: agreg | I1: comprimento corpo | J1: comprimento perna e | K1: comprimento perna d | L1: largura cefalotorax | M1: largura do abdomen | N1: observacoes | O1: obs2 | P1: obs3
A2: f01 | B2: 1 | C2: f | D2: na | E2: 1 | F2: 1 | G2: s | H2: na | I2: 2.679 | J2: 5.449 | K2: 5.518 | L2: 0.593 | M2: 0.781 | O2: Pouco gelo, caixa de isopor quente
A3: m01 | B3: 1 | C3: m | D3: c | E3: 1 | F3: 1 | G3: s | H3: na | I3: 0.524 | J3: 1.633 | K3: 1.636 | L3: 0.145 | M3: 0.121 | N3: Estava na lateral da teia, mas estava se alimentando | O3: Pouco gelo, caixa de isopor quente
A4: f02 | B4: 1 | C4: f | D4: na | E4: 1 | F4: 2 | G4: s | H4: na | I4: 2.291 | J4: na | K4: 5.65 | L4: 0.606 | M4: 0.498 | O4: Pouco gelo, caixa de isopor quente
A5: m02 | B5: 1 | C5: m | D5: c | E5: 1 | F5: 3 | G5: a | H5: 1 | I5: 0.591 | J5: 1.579 | K5: 1.824 | L5: 0.177 | M5: 0.112 | O5: Pouco gelo, caixa de isopor quente
A6: f03 | B6: 1 | C6: f | D6: na | E6: 1 | F6: 3 | G6: a | H6: 1 | I6: 1.992 | J6: 5.005 | K6: 4.844 | L6: 0.493 | M6: 0.466 | O6: Pouco gelo, caixa de isopor quente
A7: f04 | B7: 1 | C7: f | D7: na | E7: 1 | F7: 4 | G7: a | H7: 1 | I7: 2.078 | J7: na | K7: 4.665 | L7: 0.517 | M7: 0.55 | O7: Pouco gelo, caixa de isopor quente
A8: f05 | B8: 1 | C8: f | D8: na | E8: 1 | F8: 5 | G8: a | H8: 1 | I8: 2.69 | J8: 5.435 | K8: 5.301 | L8: 0.65 | M8: 0.626 | O8: Pouco gelo, caixa de isopor quente
A9: f06 | B9: 1 | C9: f | D9: na | E9: 1 | F9: 6 | G9: a | H9: 1 | I9: 2.091 | J9: 3.889 | K9: 3.883 | L9: 0.445 | M9: 0.505 | N9: Perdeu a perna durante o manejo | O9: Pouco gelo, caixa de isopor quente
A10: f07 | B10: 1 | C10: f | D10: na | E10: 1 | F10: 7 | G10: a | H10: 1 | I10: 2.293 | J10: na | K10: 5.434 | L10: 0.589 | M10: 0.496 | O10: Pouco gelo, caixa de isopor quente
A11: f08 | B11: 1 | C11: f | D11: na | E11: 1 | F11: 8 | G11: a | H11: 1 | I11: 2.358 | J11: 6.01 | K11: 5.839 | L11: 0.641 | M11: 0.51 | O11: Pouco gelo, caixa de isopor quente
A12: f09 | B12: 1 | C12: f | D12: na | E12: 1 | F12: 9 | G12: s | H12: na | I12: 2.106 | J12: 4.866 | K12: 4.676 | L12: 0.495 | M12: 0.578 | O12: Pouco gelo, caixa de isopor quente | P12: Trocou de pote
A13: m03 | B13: 1 | C13: m | D13: c | E13: 1 | F13: 10 | G13: s | H13: na | I13: 0.557 | J13: na | K13: 1.898 | L13: 0.186 | M13: 0.109 | O13: Pouco gelo, caixa de isopor quente | P13: sem a perna esquerda
A14: f10 | B14: 1 | C14: f | D14: na | E14: 1 | F14: 10 | G14: s | H14: na | I14: 2.269 | J14: 4.913 | K14: 5.062 | L14: 0.545 | M14: 0.591 | O14: Pouco gelo, caixa de isopor quente
A15: m05 | B15: 1 | C15: m | D15: c | E15: 1 | F15: 11 | G15: s | H15: na | I15: 0.888 | J15: 3.101 | K15: na | L15: 0.234 | M15: 0.17 | O15: Pouco gelo, caixa de isopor quente | P15: sem perna direita
A16: f11 | B16: 1 | C16: f | D16: na | E16: 1 | F16: 11 | G16: s | H16: na | I16: 2.707 | J16: 5.234 | K16: 4.979 | L16: 0.607 | M16: 0.739 | O16: Pouco gelo, caixa de isopor quente
A17: m06 | B17: 1 | C17: m | D17: P | E17: 1 | F17: 12 | G17: s | H17: na | I17: 0.593 | J17: na | K17: na | L17: 0.181 | M17: 0.109 | O17: Pouco gelo, caixa de isopor quente | P17: duas pernas dianteiras ausentes
A18: f12 | B18: 1 | C18: f | D18: na | E18: 1 | F18: 12 | G18: s | H18: na | I18: 2.747 | J18: 5.198 | K18: 5.162 | L18: 0.579 | M18: 0.714 | N18: se alimentou logo antes da captura | O18: Pouco gelo, caixa de isopor quente
A19: m07 | B19: 1 | C19: m | D19: c | E19: 1 | F19: 13 | G19: s | H19: na | I19: 0.659 | J19: 2.403 | K19: na | L19: 0.194 | M19: 0.109 | O19: Pouco gelo, caixa de isopor quente | P19: sem perna direita
A20: f13 | B20: 1 | C20: f | D20: na | E20: 1 | F20: 13 | G20: s | H20: na | I20: 2.472 | J20: 5.63 | K20: 5.606 | L20: 0.587 | M20: 0.583 | N20: se alimentou logo antes da captura, já havia sido marcada com tinta para outro experimento | O20: Pouco gelo, caixa de isopor quente
A21: f14 | B21: 1 | C21: f | D21: na | E21: 2 | F21: 14 | G21: s | H21: na | I21: 2.471 | J21: na | K21: 4.922 | L21: 0.526 | M21: 0.623 | O21: Pouco gelo, caixa de isopor quente | P21: Trocou de pote
A22: m08 | B22: 1 | C22: m | D22: c | E22: 2 | F22: 14 | G22: s | H22: na | I22: 0.628 | J22: na | K22: 2.066 | L22: 0.183 | M22: 0.115 | O22: Pouco gelo, caixa de isopor quente
A23: f15 | B23: 1 | C23: f | D23: na | E23: 2 | F23: 15 | G23: s | H23: na | I23: 2.69 | J23: 5.11 | K23: 5.25 | L23: 0.554 | M23: 0.654 | N23: Já havia sido marcada com tinta parra outro experimento | O23: Pouco gelo, caixa de isopor quente | P23: Trocou de pote
A24: f16 | B24: 1 | C24: f | D24: na | E24: 2 | F24: 16 | G24: s | H24: na | I24: 2.456 | J24: 4.423 | K24: 4.826 | L24: 0.532 | M24: 0.604 | O24: Pouco gelo, caixa de isopor quente
A25: f17 | B25: 1 | C25: f | D25: na | E25: 3 | F25: 17 | G25: a | H25: 2 | I25: 2.33 | J25: 5.051 | K25: 5.009 | L25: 0.484 | M25: 0.537 | O25: Pouco gelo, caixa de isopor quente | P25: Trocou de pote
A26: f18 | B26: 1 | C26: f | D26: na | E26: 3 | F26: 18 | G26: a | H26: 2 | I26: 1.941 | J26: 3.822 | K26: 3.79 | L26: 0.386 | M26: 0.498 | O26: Pouco gelo, caixa de isopor quente
A27: m09 | B27: 1 | C27: m | D27: c | E27: 3 | F27: 19 | G27: a | H27: 2 | I27: 0.899 | J27: na | K27: 3.397 | L27: 0.26 | M27: 0.177 | O27: Pouco gelo, caixa de isopor quente | P27: sem a perna esquerda
A28: f19 | B28: 1 | C28: f | D28: na | E28: 3 | F28: 19 | G28: a | H28: 2 | I28: 2.785 | J28: 5.339 | K28: 5.38 | L28: 0.559 | M28: 0.729 | O28: Pouco gelo, caixa de isopor quente
A29: m10 | B29: 1 | C29: m | D29: c | E29: 3 | F29: 20 | G29: a | H29: 2 | I29: 0.541 | J29: 1.945 | K29: na | L29: 0.145 | M29: 0.106 | O29: Pouco gelo, caixa de isopor quente | P29: sem perna direita
A30: f20 | B30: 1 | C30: f | D30: na | E30: 3 | F30: 20 | G30: a | H30: 2 | I30: 2.409 | J30: 5.147 | K30: 5.282 | L30: 0.579 | M30: 0.488 | O30: Pouco gelo, caixa de isopor quente
A31: f21 | B31: 1 | C31: f | D31: na | E31: 3 | F31: 21 | G31: a | H31: 2 | I31: 2.436 | J31: 4.675 | K31: 4.68 | L31: 0.495 | M31: 0.639 | O31: Pouco gelo, caixa de isopor quente
A32: f22 | B32: 1 | C32: f | D32: na | E32: 3 | F32: 22 | G32: a | H32: 2 | I32: 2.357 | J32: 4.461 | K32: 4.334 | L32: 0.502 | M32: 0.512 | N32: Asterisco: a posição pode ter trocado com a f23 durante a coleta | O32: Pouco gelo, caixa de isopor quente | P32: Trocou de pote
A33: f23 | B33: 1 | C33: f | D33: na | E33: 3 | F33: 23 | G33: a | H33: 2 | I33: 2.828 | J33: 5.639 | K33: 5.672 | L33: 0.588 | M33: 0.839 | N33: Asterisco: a posição pode ter trocado com a f22 durante a coleta | O33: Pouco gelo, caixa de isopor quente
A34: f24 | B34: 1 | C34: f | D34: na | E34: 3 | F34: 24 | G34: a | H34: 2 | I34: 2.179 | J34: na | K34: 4.639 | L34: 0.513 | M34: 0.425 | O34: Pouco gelo, caixa de isopor quente
A35: f25 | B35: 1 | C35: f | D35: na | E35: 3 | F35: 25 | G35: a | H35: 2 | I35: 2.693 | J35: 5.797 | K35: na | L35: 0.585 | M35: 0.551 | O35: Pouco gelo, caixa de isopor quente
A36: f26 | B36: 1 | C36: f | D36: na | E36: 3 | F36: 26 | G36: a | H36: 2 | I36: 2.393 | J36: 4.713 | K36: 4.65 | L36: 0.479 | M36: 0.609 | O36: Pouco gelo, caixa de isopor quente
A37: f27 | B37: 1 | C37: f | D37: na | E37: 3 | F37: 27 | G37: a | H37: 2 | I37: 2.462 | J37: 5.566 | K37: 5.424 | L37: 0.591 | M37: 0.583 | O37: Pouco gelo, caixa de isopor quente | P37: Trocou de pote
A38: f28 | B38: 1 | C38: f | D38: na | E38: 3 | F38: 28 | G38: a | H38: 2 | I38: 2.218 | J38: 4.043 | K38: 4.57 | L38: 0.492 | M38: 0.553 | O38: Pouco gelo, caixa de isopor quente
A39: f29 | B39: 1 | C39: f | D39: na | E39: 3 | F39: 29 | G39: a | H39: 2 | I39: 2.251 | J39: 4.719 | K39: 4.719 | L39: 0.464 | M39: 0.567 | O39: Pouco gelo, caixa de isopor quente
A40: m11 | B40: 1 | C40: m | D40: c | E40: sede | F40: 30 | G40: a | H40: 3 | I40: 0.511 | J40: 1.613 | K40: 1.701 | L40: 0.182 | M40: 0.121
...

Sheet Contagem de indivíduos
I1: CRUA
H2: Contagem de id | I2: Rótulos de Coluna
H3: Rótulos de Linha | I3: c | J3: na | K3: P | L3: Total Geral
H4: f | J4: 132 | L4: 132
H5: fe | J5: 12 | L5: 12
H6: m | I6: 59 | K6: 22 | L6: 81
H7: me | I7: 5 | K7: 6 | L7: 11
H8: Total Geral | I8: 64 | J8: 144 | K8: 28 | L8: 236
C15: SEM OS ERRADOS
B18: Contagem de id | C18: Rótulos de Coluna
C19: 1 | I19: 1 Total | J19: 2 | P19: 2 Total | Q19: Total Geral
C20: c | E20: c Total | F20: P | H20: P Total | J20: c | L20: c Total | M20: P | O20: P Total
B21: Rótulos de Linha | C21: a | D21: s | F21: a | G21: s | J21: a | K21: s | M21: a | N21: s
B22: m | C22: 7 | D22: 12 | E22: 19 | F22: 1 | G22: 1 | H22: 2 | I22: 21 | J22: 18 | K22: 22 | L22: 40 | M22: 15 | N22: 5 | O22: 20 | P22: 60 | Q22: 81
B23: Total Geral | C23: 7 | D23: 12 | E23: 19 | F23: 1 | G23: 1 | H23: 2 | I23: 21 | J23: 18 | K23: 22 | L23: 40 | M23: 15 | N23: 5 | O23: 20 | P23: 60 | Q23: 81
E35: 1 | K35: c | M35: c Total
E36: c | G36: c Total | K36: a | L36: s
E37: a | F37: s
K38: 18 | L38: 22 | M38: 40
E39: 7 | F39: 12 | G39: 19 | K39: 18 | L39: 22 | M39: 40
E40: 7 | F40: 12 | G40: 19
E44: Contagem de id | F44: Rótulos de Coluna
F45: 2 | L45: 2 Total | M45: Total Geral
F46: c | H46: c Total | I46: P | K46: P Total
E47: Rótulos de Linha | F47: a | G47: s | I47: a | J47: s
E48: m | F48: 18 | G48: 22 | H48: 40 | I48: 15 | J48: 5 | K48: 20 | L48: 60 | M48: 60
E49: Total Geral | F49: 18 | G49: 22 | H49: 40 | I49: 15 | J49: 5 | K49: 20 | L49: 60 | M49: 60
F51: Coleta 2024 | N51: Total Geral
F52: Central | I52: Periférico | L52: Total
F53: Solitária | G53: Agregada | H53: Total | I53: Solitária | J53: Agregada | K53: Total
E54: Machos | F54: 12 | G54: 7 | H54: 19 | I54: 1 | J54: 1 | K54: 2 | L54: 21 | N54: 81
F56: Coleta 2025
F57: Central | I57: Periférico | L57: Total
F58: Solitária | G58: Agregada | H58: Total | I58: Solitária | J58: Agregada | K58: Total
E59: Machos | F59: 22 | G59: 18 | H59: 40 | I59: 5 | J59: 15 | K59: 20 | L59: 60

Sheet Planilha1
F9: Rótulos de Coluna
F10: 1 | G10: 2 | H10: Total Geral
E11: Máx. de agreg | F11: 5 | G11: 12 | H11: 12
Z12: Agregação | AA12: 1 | AB12: 2 | AC12: 3 | AD12: 4 | AE12: 5 | AF12: 6 | AG12: 7 | AH12: 8 | AI12: 9 | AJ12: 10 | AK12: 11 | AL12: 12
Z13: Teias | AA13: 6 | AB13: 13 | AC13: 15 | AD13: 4 | AE13: 5 | AF13: 8 | AG13: 3 | AH13: 3 | AI13: 5 | AJ13: 3 | AK13: 4 | AL13: 3
B14: =81/132 -> 0.61363636
F16: Coleta 2024 | I16: Coleta 2025
F17: Agregadas | G17: Solitárias | H17: Total | I17: Agregadas | J17: Solitárias | K17: Total | L17: Total Geral
E18: Fêmeas | F18: 43 | G18: 32 | H18: 75 | I18: 29 | J18: 28 | K18: 57 | L18: 132
E19: Machos | F19: 8 | G19: 13 | H19: 21 | I19: 33 | J19: 27 | K19: 60 | L19: 81
E20: Total Geral | H20: 96 | K20: 117 | L20: 213
E23: Agregação | F23: 1 | G23: 2 | H23: 3 | I23: 4 | J23: 5 | K23: 6 | L23: 7 | M23: 8 | N23: 9 | O23: 10 | P23: 11 | Q23: 12
E24: Teias | F24: 6 | G24: 13 | H24: 15 | I24: 4 | J24: 5 | K24: 8 | L24: 3 | M24: 3 | N24: 5 | O24: 3 | P24: 4 | Q24: 3
F27: 1 | H27: 1 Total | I27: 2 | K27: 2 Total | L27: Total Geral
E28: Rótulos de Linha | F28: c | G28: P | I28: c | J28: P
E29: m | F29: 19 | G29: 2 | H29: 21 | I29: 40 | J29: 20 | K29: 60 | L29: 81
F31: Coleta 2024 | I31: Coleta 2025
F32: Central | G32: Periférico | H32: Total | I32: Central | J32: Periférico | K32: Total
E33: Macho | F33: 19 | G33: 2 | H33: 21 | I33: 40 | J33: 20 | K33: 60

Sheet H1 com todo mundo
A1: id | B1: coleta | C1: sexo | D1: posicao | E1: trilha | F1: idteia | G1: situacaoteia | H1: agreg | I1: cefafem | J1: cefamac | K1: data | L1: quinz
A2: f03 | B2: 1 | C2: f | D2: na | E2: 1 | F2: 3 | G2: a | H2: 1 | I2: 0.493 | J2: 0.177 | K2: =VLOOKUP(TRIM(A2 & ""), 'planilha crua'!$A$2:$B$10000, 2, FALSE) -> 45401 | L2: =INT((DATE(2000, MONTH(K2), DAY(K2)) - DATE(2000, 3, 12)) / 15) + 1 -> 3
A3: f19 | B3: 1 | C3: f | D3: na | E3: 3 | F3: 19 | G3: a | H3: 2 | I3: 0.559 | J3: 0.26 | K3: =VLOOKUP(TRIM(A3 & ""), 'planilha crua'!$A$2:$B$10000, 2, FALSE) -> 45401 | L3: =INT((DATE(2000, MONTH(K3), DAY(K3)) - DATE(2000, 3, 12)) / 15) + 1 -> 3
A4: f20 | B4: 1 | C4: f | D4: na | E4: 3 | F4: 20 | G4: a | H4: 2 | I4: 0.579 | J4: 0.145 | K4: =VLOOKUP(TRIM(A4 & ""), 'planilha crua'!$A$2:$B$10000, 2, FALSE) -> 45401 | L4: =INT((DATE(2000, MONTH(K4), DAY(K4)) - DATE(2000, 3, 12)) / 15) + 1 -> 3
A5: f30 | B5: 1 | C5: f | D5: na | E5: sede | F5: 30 | G5: a | H5: 3 | I5: 0.54 | J5: 0.182 | K5: =VLOOKUP(TRIM(A5 & ""), 'planilha crua'!$A$2:$B$10000, 2, FALSE) -> 45404 | L5: =INT((DATE(2000, MONTH(K5), DAY(K5)) - DATE(2000, 3, 12)) / 15) + 1 -> 3
A6: f45 | B6: 1 | C6: f | D6: na | E6: sede | F6: 45 | G6: a | H6: 4 | I6: 0.35 | J6: 0.171 | K6: =VLOOKUP(TRIM(A6 & ""), 'planilha crua'!$A$2:$B$10000, 2, FALSE) -> 45404 | L6: =INT((DATE(2000, MONTH(K6), DAY(K6)) - DATE(2000, 3, 12)) / 15) + 1 -> 3
A7: f45 | B7: 1 | C7: f | D7: na | E7: sede | F7: 45 | G7: a | H7: 4 | I7: 0.35 | J7: 0.144 | K7: =VLOOKUP(TRIM(A7 & ""), 'planilha crua'!$A$2:$B$10000, 2, FALSE) -> 45404 | L7: =INT((DATE(2000, MONTH(K7), DAY(K7)) - DATE(2000, 3, 12)) / 15) + 1 -> 3
A8: f46 | B8: 1 | C8: f | D8: na | E8: sede | F8: 46 | G8: a | H8: 4 | I8: 0.497 | J8: 0.167 | K8: =VLOOKUP(TRIM(A8 & ""), 'planilha crua'!$A$2:$B$10000, 2, FALSE) -> 45404 | L8: =INT((DATE(2000, MONTH(K8), DAY(K8)) - DATE(2000, 3, 12)) / 15) + 1 -> 3
A9: f61 | B9: 1 | C9: f | D9: na | E9: 5 | F9: 61 | G9: a | H9: 5 | I9: 0.52 | J9: 0.265 | K9: =VLOOKUP(TRIM(A9 & ""), 'planilha crua'!$A$2:$B$10000, 2, FALSE) -> 45412 | L9: =INT((DATE(2000, MONTH(K9), DAY(K9)) - DATE(2000, 3, 12)) / 15) + 1 -> 4
A10: f84 | B10: 2 | C10: f | D10: na | E10: 3 | F10: 84 | G10: a | H10: 6 | I10: 0.498 | J10: 0.207 | K10: =VLOOKUP(TRIM(A10 & ""), 'planilha crua'!$A$2:$B$10000, 2, FALSE) -> 45728 | L10: =INT((DATE(2000, MONTH(K10), DAY(K10)) - DATE(2000, 3, 12)) / 15) + 1 -> 1
A11: f85 | B11: 2 | C11: f | D11: na | E11: 3 | F11: 85 | G11: a | H11: 6 | I11: 0.545 | J11: 0.152 | K11: =VLOOKUP(TRIM(A11 & ""), 'planilha crua'!$A$2:$B$10000, 2, FALSE) -> 45728 | L11: =INT((DATE(2000, MONTH(K11), DAY(K11)) - DATE(2000, 3, 12)) / 15) + 1 -> 1
A12: f85 | B12: 2 | C12: f | D12: na | E12: 3 | F12: 85 | G12: a | H12: 6 | I12: 0.545 | J12: 0.286 | K12: =VLOOKUP(TRIM(A12 & ""), 'planilha crua'!$A$2:$B$10000, 2, FALSE) -> 45728 | L12: =INT((DATE(2000, MONTH(K12), DAY(K12)) - DATE(2000, 3, 12)) / 15) + 1 -> 1
A13: f86 | B13: 2 | C13: f | D13: na | E13: 3 | F13: 86 | G13: a | H13: 6 | I13: 0.475 | J13: 0.139 | K13: =VLOOKUP(TRIM(A13 & ""), 'planilha crua'!$A$2:$B$10000, 2, FALSE) -> 45728 | L13: =INT((DATE(2000, MONTH(K13), DAY(K13)) - DATE(2000, 3, 12)) / 15) + 1 -> 1
A14: f86 | B14: 2 | C14: f | D14: na | E14: 3 | F14: 86 | G14: a | H14: 6 | I14: 0.475 | J14: 0.208 | K14: =VLOOKUP(TRIM(A14 & ""), 'planilha crua'!$A$2:$B$10000, 2, FALSE) -> 45728 | L14: =INT((DATE(2000, MONTH(K14), DAY(K14)) - DATE(2000, 3, 12)) / 15) + 1 -> 1
A15: f86 | B15: 2 | C15: f | D15: na | E15: 3 | F15: 86 | G15: a | H15: 6 | I15: 0.475 | J15: 0.2 | K15: =VLOOKUP(TRIM(A15 & ""), 'planilha crua'!$A$2:$B$10000, 2, FALSE) -> 45728 | L15: =INT((DATE(2000, MONTH(K15), DAY(K15)) - DATE(2000, 3, 12)) / 15) + 1 -> 1
A16: f86 | B16: 2 | C16: f | D16: na | E16: 3 | F16: 86 | G16: a | H16: 6 | I16: 0.475 | J16: 0.175 | K16: =VLOOKUP(TRIM(A16 & ""), 'planilha crua'!$A$2:$B$10000, 2, FALSE) -> 45728 | L16: =INT((DATE(2000, MONTH(K16), DAY(K16)) - DATE(2000, 3, 12)) / 15) + 1 -> 1
A17: f86 | B17: 2 | C17: f | D17: na | E17: 3 | F17: 86 | G17: a | H17: 6 | I17: 0.475 | J17: 0.166 | K17: =VLOOKUP(TRIM(A17 & ""), 'planilha crua'!$A$2:$B$10000, 2, FALSE) -> 45728 | L17: =INT((DATE(2000, MONTH(K17), DAY(K17)) - DATE(2000, 3, 12)) / 15) + 1 -> 1
A18: f86 | B18: 2 | C18: f | D18: na | E18: 3 | F18: 86 | G18: a | H18: 6 | I18: 0.475 | J18: 0.191 | K18: =VLOOKUP(TRIM(A18 & ""), 'planilha crua'!$A$2:$B$10000, 2, FALSE) -> 45728 | L18: =INT((DATE(2000, MONTH(K18), DAY(K18)) - DATE(2000, 3, 12)) / 15) + 1 -> 1
A19: f86 | B19: 2 | C19: f | D19: na | E19: 3 | F19: 86 | G19: a | H19: 6 | I19: 0.475 | J19: 0.182 | K19: =VLOOKUP(TRIM(A19 & ""), 'planilha crua'!$A$2:$B$10000, 2, FALSE) -> 45728 | L19: =INT((DATE(2000, MONTH(K19), DAY(K19)) - DATE(2000, 3, 12)) / 15) + 1 -> 1
A20: f86 | B20: 2 | C20: f | D20: na | E20: 3 | F20: 86 | G20: a | H20: 6 | I20: 0.475 | J20: 0.192 | K20: =VLOOKUP(TRIM(A20 & ""), 'planilha crua'!$A$2:$B$10000, 2, FALSE) -> 45728 | L20: =INT((DATE(2000, MONTH(K20), DAY(K20)) - DATE(2000, 3, 12)) / 15) + 1 -> 1
... A82: f133 | B82: 2 | C82: f | D82: na | E82: 1 | F82: 133 | G82: s | H82: 52 | I82: 0.473 | J82: 0.224 | K82: =VLOOKUP(TRIM(A82 & ""), 'planilha crua'!$A$2:$B$10000, 2, FALSE) -> 45756 | L82: =INT((DATE(2000, MONTH(K82), DAY(K82)) - DATE(2000, 3, 12)) / 15) + 1 -> 2

Sheet teiah12cq
A1: id | B1: coleta | C1: sexo | D1: posicao | E1: trilha | F1: idteia | G1: situacaoteia | H1: agreg | I1: cefafem | J1: cefamac | K1: data | L1: quinz
A2: f03 | B2: 1 | C2: f | D2: na | E2: 1 | F2: 3 | G2: a | H2: 1 | I2: 0.493 | J2: 0.177 | K2: =VLOOKUP(TRIM(A2 & ""), 'planilha crua'!$A$2:$B$10000, 2, FALSE) -> 45401 | L2: =INT((DATE(2000, MONTH(K2), DAY(K2)) - DATE(2000, 3, 12)) / 15) + 1 -> 3
A3: f19 | B3: 1 | C3: f | D3: na | E3: 3 | F3: 19 | G3: a | H3: 2 | I3: 0.559 | J3: 0.26 | K3: =VLOOKUP(TRIM(A3 & ""), 'planilha crua'!$A$2:$B$10000, 2, FALSE) -> 45401 | L3: =INT((DATE(2000, MONTH(K3), DAY(K3)) - DATE(2000, 3, 12)) / 15) + 1 -> 3
A4: f20 | B4: 1 | C4: f | D4: na | E4: 3 | F4: 20 | G4: a | H4: 2 | I4: 0.579 | J4: 0.145 | K4: =VLOOKUP(TRIM(A4 & ""), 'planilha crua'!$A$2:$B$10000, 2, FALSE) -> 45401 | L4: =INT((DATE(2000, MONTH(K4), DAY(K4)) - DATE(2000, 3, 12)) / 15) + 1 -> 3
A5: f30 | B5: 1 | C5: f | D5: na | E5: sede | F5: 30 | G5: a | H5: 3 | I5: 0.54 | J5: 0.182 | K5: =VLOOKUP(TRIM(A5 & ""), 'planilha crua'!$A$2:$B$10000, 2, FALSE) -> 45404 | L5: =INT((DATE(2000, MONTH(K5), DAY(K5)) - DATE(2000, 3, 12)) / 15) + 1 -> 3
A6: f45 | B6: 1 | C6: f | D6: na | E6: sede | F6: 45 | G6: a | H6: 4 | I6: 0.35 | J6: 0.171 | K6: =VLOOKUP(TRIM(A6 & ""), 'planilha crua'!$A$2:$B$10000, 2, FALSE) -> 45404 | L6: =INT((DATE(2000, MONTH(K6), DAY(K6)) - DATE(2000, 3, 12)) / 15) + 1 -> 3
A7: f46 | B7: 1 | C7: f | D7: na | E7: sede | F7: 46 | G7: a | H7: 4 | I7: 0.497 | J7: 0.167 | K7: =VLOOKUP(TRIM(A7 & ""), 'planilha crua'!$A$2:$B$10000, 2, FALSE) -> 45404 | L7: =INT((DATE(2000, MONTH(K7), DAY(K7)) - DATE(2000, 3, 12)) / 15) + 1 -> 3
A8: f61 | B8: 1 | C8: f | D8: na | E8: 5 | F8: 61 | G8: a | H8: 5 | I8: 0.52 | J8: 0.265 | K8: =VLOOKUP(TRIM(A8 & ""), 'planilha crua'!$A$2:$B$10000, 2, FALSE) -> 45412 | L8: =INT((DATE(2000, MONTH(K8), DAY(K8)) - DATE(2000, 3, 12)) / 15) + 1 -> 4
A9: f84 | B9: 2 | C9: f | D9: na | E9: 3 | F9: 84 | G9: a | H9: 6 | I9: 0.498 | J9: 0.207 | K9: =VLOOKUP(TRIM(A9 & ""), 'planilha crua'!$A$2:$B$10000, 2, FALSE) -> 45728 | L9: =INT((DATE(2000, MONTH(K9), DAY(K9)) - DATE(2000, 3, 12)) / 15) + 1 -> 1
A10: f85 | B10: 2 | C10: f | D10: na | E10: 3 | F10: 85 | G10: a | H10: 6 | I10: 0.545 | J10: 0.286 | K10: =VLOOKUP(TRIM(A10 & ""), 'planilha crua'!$A$2:$B$10000, 2, FALSE) -> 45728 | L10: =INT((DATE(2000, MONTH(K10), DAY(K10)) - DATE(2000, 3, 12)) / 15) + 1 -> 1
A11: f86 | B11: 2 | C11: f | D11: na | E11: 3 | F11: 86 | G11: a | H11: 6 | I11: 0.475 | J11: 0.2 | K11: =VLOOKUP(TRIM(A11 & ""), 'planilha crua'!$A$2:$B$10000, 2, FALSE) -> 45728 | L11: =INT((DATE(2000, MONTH(K11), DAY(K11)) - DATE(2000, 3, 12)) / 15) + 1 -> 1
A12: f88 | B12: 2 | C12: f | D12: na | E12: 3 | F12: 88 | G12: a | H12: 7 | I12: 0.384 | J12: 0.166 | K12: =VLOOKUP(TRIM(A12 & ""), 'planilha crua'!$A$2:$B$10000, 2, FALSE) -> 45728 | L12: =INT((DATE(2000, MONTH(K12), DAY(K12)) - DATE(2000, 3, 12)) / 15) + 1 -> 1
A13: f90 | B13: 2 | C13: f | D13: na | E13: 3 | F13: 90 | G13: a | H13: 7 | I13: 0.483 | J13: 0.267 | K13: =VLOOKUP(TRIM(A13 & ""), 'planilha crua'!$A$2:$B$10000, 2, FALSE) -> 45728 | L13: =INT((DATE(2000, MONTH(K13), DAY(K13)) - DATE(2000, 3, 12)) / 15) + 1 -> 1
A14: f92 | B14: 2 | C14: f | D14: na | E14: 6 | F14: 92 | G14: a | H14: 8 | I14: 0.584 | J14: 0.191 | K14: =VLOOKUP(TRIM(A14 & ""), 'planilha crua'!$A$2:$B$10000, 2, FALSE) -> 45728 | L14: =INT((DATE(2000, MONTH(K14), DAY(K14)) - DATE(2000, 3, 12)) / 15) + 1 -> 1
A15: f94 | B15: 2 | C15: f | D15: na | E15: 6 | F15: 94 | G15: a | H15: 8 | I15: 0.502 | J15: 0.213 | K15: =VLOOKUP(TRIM(A15 & ""), 'planilha crua'!$A$2:$B$10000, 2, FALSE) -> 45728 | L15: =INT((DATE(2000, MONTH(K15), DAY(K15)) - DATE(2000, 3, 12)) / 15) + 1 -> 1
A16: f95 | B16: 2 | C16: f | D16: na | E16: 1 | F16: 95 | G16: a | H16: 9 | I16: 0.571 | J16: 0.176 | K16: =VLOOKUP(TRIM(A16 & ""), 'planilha crua'!$A$2:$B$10000, 2, FALSE) -> 45741 | L16: =INT((DATE(2000, MONTH(K16), DAY(K16)) - DATE(2000, 3, 12)) / 15) + 1 -> 1
A17: f97 | B17: 2 | C17: f | D17: na | E17: 1 | F17: 97 | G17: a | H17: 9 | I17: 0.349 | J17: 0.184 | K17: =VLOOKUP(TRIM(A17 & ""), 'planilha crua'!$A$2:$B$10000, 2, FALSE) -> 45741 | L17: =INT((DATE(2000, MONTH(K17), DAY(K17)) - DATE(2000, 3, 12)) / 15) + 1 -> 1
A18: f98 | B18: 2 | C18: f | D18: na | E18: 1 | F18: 98 | G18: a | H18: 9 | I18: 0.333 | J18: 0.206 | K18: =VLOOKUP(TRIM(A18 & ""), 'planilha crua'!$A$2:$B$10000, 2, FALSE) -> 45741 | L18: =INT((DATE(2000, MONTH(K18), DAY(K18)) - DATE(2000, 3, 12)) / 15) + 1 -> 1
A19: f99 | B19: 2 | C19: f | D19: na | E19: 1 | F19: 99 | G19: a | H19: 9 | I19: 0.401 | J19: 0.216 | K19: =VLOOKUP(TRIM(A19 & ""), 'planilha crua'!$A$2:$B$10000, 2, FALSE) -> 45741 | L19: =INT((DATE(2000, MONTH(K19), DAY(K19)) - DATE(2000, 3, 12)) / 15) + 1 -> 1
... A60: f133 | B60: 2 | C60: f | D60: na | E60: 1 | F60: 133 | G60: s | H60: 52 | I60: 0.473 | J60: 0.224 | K60: =VLOOKUP(TRIM(A60 & ""), 'planilha crua'!$A$2:$B$10000, 2, FALSE) -> 45756 | L60: =INT((DATE(2000, MONTH(K60), DAY(K60)) - DATE(2000, 3, 12)) / 15) + 1 -> 2

Sheet teiah22q
A1: id | B1: coleta | C1: sexo | D1: posicao | E1: trilha | F1: idteia | G1: situacaoteia | H1: agreg | I1: cefalotorax | J1: nacomp | K1: acomp | L1: nacomp2 | M1: data | N1: quinz
A2: f01 | B2: 1 | C2: f | D2: na | E2: 1 | F2: 1 | G2: s | H2: 13 | I2: 0.593 | J2: 2 | K2: s | L2: =J2-1 -> 1 | M2: =VLOOKUP(TRIM(A2 & ""), 'planilha crua'!$A$2:$B$10000, 2, FALSE) -> 45401 | N2: =INT((DATE(2000, MONTH(M2), DAY(M2)) - DATE(2000, 3, 12)) / 15) + 1 -> 3
A3: f02 | B3: 1 | C3: f | D3: na | E3: 1 | F3: 2 | G3: s | H3: 14 | I3: 0.606 | J3: 1 | K3: n | L3: =J3-1 -> 0 | M3: =VLOOKUP(TRIM(A3 & ""), 'planilha crua'!$A$2:$B$10000, 2, FALSE) -> 45401 | N3: =INT((DATE(2000, MONTH(M3), DAY(M3)) - DATE(2000, 3, 12)) / 15) + 1 -> 3
A4: f03 | B4: 1 | C4: f | D4: na | E4: 1 | F4: 3 | G4: a | H4: 1 | I4: 0.493 | J4: 2 | K4: s | L4: =J4-1 -> 1 | M4: =VLOOKUP(TRIM(A4 & ""), 'planilha crua'!$A$2:$B$10000, 2, FALSE) -> 45401 | N4: =INT((DATE(2000, MONTH(M4), DAY(M4)) - DATE(2000, 3, 12)) / 15) + 1 -> 3
A5: f04 | B5: 1 | C5: f | D5: na | E5: 1 | F5: 4 | G5: a | H5: 1 | I5: 0.517 | J5: 1 | K5: n | L5: =J5-1 -> 0 | M5: =VLOOKUP(TRIM(A5 & ""), 'planilha crua'!$A$2:$B$10000, 2, FALSE) -> 45401 | N5: =INT((DATE(2000, MONTH(M5), DAY(M5)) - DATE(2000, 3, 12)) / 15) + 1 -> 3
A6: f05 | B6: 1 | C6: f | D6: na | E6: 1 | F6: 5 | G6: a | H6: 1 | I6: 0.65 | J6: 1 | K6: n | L6: =J6-1 -> 0 | M6: =VLOOKUP(TRIM(A6 & ""), 'planilha crua'!$A$2:$B$10000, 2, FALSE) -> 45401 | N6: =INT((DATE(2000, MONTH(M6), DAY(M6)) - DATE(2000, 3, 12)) / 15) + 1 -> 3
A7: f06 | B7: 1 | C7: f | D7: na | E7: 1 | F7: 6 | G7: a | H7: 1 | I7: 0.445 | J7: 1 | K7: n | L7: =J7-1 -> 0 | M7: =VLOOKUP(TRIM(A7 & ""), 'planilha crua'!$A$2:$B$10000, 2, FALSE) -> 45401 | N7: =INT((DATE(2000, MONTH(M7), DAY(M7)) - DATE(2000, 3, 12)) / 15) + 1 -> 3
A8: f07 | B8: 1 | C8: f | D8: na | E8: 1 | F8: 7 | G8: a | H8: 1 | I8: 0.589 | J8: 1 | K8: n | L8: =J8-1 -> 0 | M8: =VLOOKUP(TRIM(A8 & ""), 'planilha crua'!$A$2:$B$10000, 2, FALSE) -> 45401 | N8: =INT((DATE(2000, MONTH(M8), DAY(M8)) - DATE(2000, 3, 12)) / 15) + 1 -> 3
A9: f08 | B9: 1 | C9: f | D9: na | E9: 1 | F9: 8 | G9: a | H9: 1 | I9: 0.641 | J9: 1 | K9: n | L9: =J9-1 -> 0 | M9: =VLOOKUP(TRIM(A9 & ""), 'planilha crua'!$A$2:$B$10000, 2, FALSE) -> 45401 | N9: =INT((DATE(2000, MONTH(M9), DAY(M9)) - DATE(2000, 3, 12)) / 15) + 1 -> 3
A10: f09 | B10: 1 | C10: f | D10: na | E10: 1 | F10: 9 | G10: s | H10: 15 | I10: 0.495 | J10: 1 | K10: n | L10: =J10-1 -> 0 | M10: =VLOOKUP(TRIM(A10 & ""), 'planilha crua'!$A$2:$B$10000, 2, FALSE) -> 45401 | N10: =INT((DATE(2000, MONTH(M10), DAY(M10)) - DATE(2000, 3, 12)) / 15) + 1 -> 3
A11: f10 | B11: 1 | C11: f | D11: na | E11: 1 | F11: 10 | G11: s | H11: 16 | I11: 0.545 | J11: 2 | K11: s | L11: =J11-1 -> 1 | M11: =VLOOKUP(TRIM(A11 & ""), 'planilha crua'!$A$2:$B$10000, 2, FALSE) -> 45401 | N11: =INT((DATE(2000, MONTH(M11), DAY(M11)) - DATE(2000, 3, 12)) / 15) + 1 -> 3
A12: f11 | B12: 1 | C12: f | D12: na | E12: 1 | F12: 11 | G12: s | H12: 17 | I12: 0.607 | J12: 2 | K12: s | L12: =J12-1 -> 1 | M12: =VLOOKUP(TRIM(A12 & ""), 'planilha crua'!$A$2:$B$10000, 2, FALSE) -> 45401 | N12: =INT((DATE(2000, MONTH(M12), DAY(M12)) - DATE(2000, 3, 12)) / 15) + 1 -> 3
A13: f12 | B13: 1 | C13: f | D13: na | E13: 1 | F13: 12 | G13: s | H13: 18 | I13: 0.579 | J13: 2 | K13: s | L13: =J13-1 -> 1 | M13: =VLOOKUP(TRIM(A13 & ""), 'planilha crua'!$A$2:$B$10000, 2, FALSE) -> 45401 | N13: =INT((DATE(2000, MONTH(M13), DAY(M13)) - DATE(2000, 3, 12)) / 15) + 1 -> 3
... A30: f29 | B30: 1 | C30: f | D30: na | E30: 3 | F30: 29 | G30: a | H30: 2 | I30: 0.464 | J30: 1 | K30: n | L30: =J30-1 -> 0 | M30: =VLOOKUP(TRIM(A30 & ""), 'planilha crua'!$A$2:$B$10000, 2, FALSE) -> 45401 | N30: =INT((DATE(2000, MONTH(M30), DAY(M30)) - DATE(2000, 3, 12)) / 15) + 1 -> 3
A31: f30 | B31: 1 | C31: f | D31: na | E31: sede | F31: 30 | G31: a | H31: 3 | I31: 0.54 | J31: 2 | K31: s | L31: =J31-1 -> 1 | M31: =VLOOKUP(TRIM(A31 & ""), 'planilha crua'!$A$2:$B$10000, 2, FALSE) -> 45404 | N31: =INT((DATE(2000, MONTH(M31), DAY(M31)) - DATE(2000, 3, 12)) / 15) + 1 -> 3
A32: f31 | B32: 1 | C32: f | D32: na | E32: sede | F32: 31 | G32: a | H32: 3 | I32: 0.52 | J32: 1 | K32: n | L32: =J32-1 -> 0 | M32: =VLOOKUP(TRIM(A32 & ""), 'planilha crua'!$A$2:$B$10000, 2, FALSE) -> 45404 | N32: =INT((DATE(2000, MONTH(M32), DAY(M32)) - DATE(2000, 3, 12)) / 15) + 1 -> 3
A33: f32 | B33: 1 | C33: f | D33: na | E33: sede | F33: 32 | G33: a | H33: 3 | I33: 0.569 | J33: 1 | K33: n | L33: =J33-1 -> 0 | M33: =VLOOKUP(TRIM(A33 & ""), 'planilha crua'!$A$2:$B$10000, 2, FALSE) -> 45404 | N33: =INT((DATE(2000, MONTH(M33), DAY(M33)) - DATE(2000, 3, 12)) / 15) + 1 -> 3
A34: f33 | B34: 1 | C34: f | D34: na | E34: sede | F34: 33 | G34: a | H34: 3 | I34: 0.486 | J34: 1 | K34: n | L34: =J34-1 -> 0 | M34: =VLOOKUP(TRIM(A34 & ""), 'planilha crua'!$A$2:$B$10000, 2, FALSE) -> 45404 | N34: =INT((DATE(2000, MONTH(M34), DAY(M34)) - DATE(2000, 3, 12)) / 15) + 1 -> 3
A35: f34 | B35: 1 | C35: f | D35: na | E35: sede | F35: 34 | G35: a | H35: 3 | I35: 0.425 | J35: 1 | K35: n | L35: =J35-1 -> 0 | M35: =VLOOKUP(TRIM(A35 & ""), 'planilha crua'!$A$2:$B$10000, 2, FALSE) -> 45404 | N35: =INT((DATE(2000, MONTH(M35), DAY(M35)) - DATE(2000, 3, 12)) / 15) + 1 -> 3
A36: f35 | B36: 1 | C36: f | D36: na | E36: sede | F36: 35 | G36: a | H36: 3 | I36: 0.617 | J36: 1 | K36: n | L36: =J36-1 -> 0 | M36: =VLOOKUP(TRIM(A36 & ""), 'planilha crua'!$A$2:$B$10000, 2, FALSE) -> 45404 | N36: =INT((DATE(2000, MONTH(M36), DAY(M36)) - DATE(2000, 3, 12)) / 15) + 1 -> 3
A37: f36 | B37: 1 | C37: f | D37: na | E37: sede | F37: 36 | G37: a | H37: 3 | I37: 0.554 | J37: 1 | K37: n | L37: =J37-1 -> 0 | M37: =VLOOKUP(TRIM(A37 & ""), 'planilha crua'!$A$2:$B$10000, 2, FALSE) -> 45404 | N37: =INT((DATE(2000, MONTH(M37), DAY(M37)) - DATE(2000, 3, 12)) / 15) + 1 -> 3
A38: f37 | B38: 1 | C38: f | D38: na | E38: sede | F38: 37 | G38: a | H38: 3 | I38: 0.594 | J38: 1 | K38: n | L38: =J38-1 -> 0 | M38: =VLOOKUP(TRIM(A38 & ""), 'planilha crua'!$A$2:$B$10000, 2, FALSE) -> 45404 | N38: =INT((DATE(2000, MONTH(M38), DAY(M38)) - DATE(2000, 3, 12)) / 15) + 1 -> 3
A39: f38 | B39: 1 | C39: f | D39: na | E39: sede | F39: 38 | G39: a | H39: 3 | I39: 0.564 | J39: 1 | K39: n | L39: =J39-1 -> 0 | M39: =VLOOKUP(TRIM(A39 & ""), 'planilha crua'!$A$2:$B$10000, 2, FALSE) -> 45404 | N39: =INT((DATE(2000, MONTH(M39), DAY(M39)) - DATE(2000, 3, 12)) / 15) + 1 -> 3
A40: f39 | B40: 1 | C40: f | D40: na | E40: sede | F40: 39 | G40: a | H40: 3 | I40: 0.62 | J40: 1 | K40: n | L40: =J40-1 -> 0 | M40: =VLOOKUP(TRIM(A40 & ""), 'planilha crua'!$A$2:$B$10000, 2, FALSE) -> 45404 | N40: =INT((DATE(2000, MONTH(M40), DAY(M40)) - DATE(2000, 3, 12)) / 15) + 1 -> 3
A41: f40 | B41: 1 | C41: f | D41: na | E41: sede | F41: 40 | G41: a | H41: 3 | I41: 0.476 | J41: 1 | K41: n | L41: =J41-1 -> 0 | M41: =VLOOKUP(TRIM(A41 & ""), 'planilha crua'!$A$2:$B$10000, 2, FALSE) -> 45404 | N41: =INT((DATE(2000, MONTH(M41), DAY(M41)) - DATE(2000, 3, 12)) / 15) + 1 -> 3
A42: f41 | B42: 1 | C42: f | D42: na | E42: sede | F42: 41 | G42: a | H42: 3 | I42: 0.557 | J42: 1 | K42: n | L42: =J42-1 -> 0 | M42: =VLOOKUP(TRIM(A42 & ""), 'planilha crua'!$A$2:$B$10000, 2, FALSE) -> 45404 | N42: =INT((DATE(2000, MONTH(M42), DAY(M42)) - DATE(2000, 3, 12)) / 15) + 1 -> 3
... A49: f48 | B49: 1 | C49: f | D49: na | E49: sede | F49: 48 | G49: a | H49: 4 | I49: 0.543 | J49: 1 | K49: n | L49: =J49-1 -> 0 | M49: =VLOOKUP(TRIM(A49 & ""), 'planilha crua'!$A$2:$B$10000, 2, FALSE) -> 45404 | N49: =INT((DATE(2000, MONTH(M49), DAY(M49)) - DATE(2000, 3, 12)) / 15) + 1 -> 3
A50: f49 | B50: 1 | C50: f | D50: na | E50: 1 | F50: 49 | G50: s | H50: 23 | I50: 0.63 | J50: 1 | K50: n | L50: =J50-1 -> 0 | M50: =VLOOKUP(TRIM(A50 & ""), 'planilha crua'!$A$2:$B$10000, 2, FALSE) -> 45407 | N50: =INT((DATE(2000, MONTH(M50), DAY(M50)) - DATE(2000, 3, 12)) / 15) + 1 -> 3
A51: f50 | B51: 1 | C51: f | D51: na | E51: 1 | F51: 50 | G51: s | H51: 24 | I51: 0.469 | J51: 1 | K51: n | L51: =J51-1 -> 0 | M51: =VLOOKUP(TRIM(A51 & ""), 'planilha crua'!$A$2:$B$10000, 2, FALSE) -> 45407 | N51: =INT((DATE(2000, MONTH(M51), DAY(M51)) - DATE(2000, 3, 12)) / 15) + 1 -> 3
A52: f51 | B52: 1 | C52: f | D52: na | E52: 4 | F52: 51 | G52: s | H52: 25 | I52: 0.453 | J52: 2 | K52: s | L52: =J52-1 -> 1 | M52: =VLOOKUP(TRIM(A52 & ""), 'planilha crua'!$A$2:$B$10000, 2, FALSE) -> 45407 | N52: =INT((DATE(2000, MONTH(M52), DAY(M52)) - DATE(2000, 3, 12)) / 15) + 1 -> 3
A53: f52 | B53: 1 | C53: f | D53: na | E53: 4 | F53: 52 | G53: s | H53: 26 | I53: 0.599 | J53: 2 | K53: s | L53: =J53-1 -> 1 | M53: =VLOOKUP(TRIM(A53 & ""), 'planilha crua'!$A$2:$B$10000, 2, FALSE) -> 45407 | N53: =INT((DATE(2000, MONTH(M53), DAY(M53)) - DATE(2000, 3, 12)) / 15) + 1 -> 3
A54: f53 | B54: 1 | C54: f | D54: na | E54: 4 | F54: 53 | G54: s | H54: 27 | I54: 0.458 | J54: 1 | K54: n | L54: =J54-1 -> 0 | M54: =VLOOKUP(TRIM(A54 & ""), 'planilha crua'!$A$2:$B$10000, 2, FALSE) -> 45407 | N54: =INT((DATE(2000, MONTH(M54), DAY(M54)) - DATE(2000, 3, 12)) / 15) + 1 -> 3
A55: f54 | B55: 1 | C55: f | D55: na | E55: 4 | F55: 54 | G55: s | H55: 28 | I55: 0.519 | J55: 2 | K55: s | L55: =J55-1 -> 1 | M55: =VLOOKUP(TRIM(A55 & ""), 'planilha crua'!$A$2:$B$10000, 2, FALSE) -> 45407 | N55: =INT((DATE(2000, MONTH(M55), DAY(M55)) - DATE(2000, 3, 12)) / 15) + 1 -> 3
A56: f55 | B56: 1 | C56: f | D56: na | E56: 3 | F56: 55 | G56: s | H56: 29 | I56: 0.562 | J56: 2 | K56: s | L56: =J56-1 -> 1 | M56: =VLOOKUP(TRIM(A56 & ""), 'planilha crua'!$A$2:$B$10000, 2, FALSE) -> 45407 | N56: =INT((DATE(2000, MONTH(M56), DAY(M56)) - DATE(2000, 3, 12)) / 15) + 1 -> 3
A57: f56 | B57: 1 | C57: f | D57: na | E57: 3 | F57: 56 | G57: s | H57: 30 | I57: 0.561 | J57: 2 | K57: s | L57: =J57-1 -> 1 | M57: =VLOOKUP(TRIM(A57 & ""), 'planilha crua'!$A$2:$B$10000, 2, FALSE) -> 45407 | N57: =INT((DATE(2000, MONTH(M57), DAY(M57)) - DATE(2000, 3, 12)) / 15) + 1 -> 3
A58: f57 | B58: 1 | C58: f | D58: na | E58: 3 | F58: 57 | G58: s | H58: 31 | I58: 0.482 | J58: 2 | K58: s | L58: =J58-1 -> 1 | M58: =VLOOKUP(TRIM(A58 & ""), 'planilha crua'!$A$2:$B$10000, 2, FALSE) -> 45407 | N58: =INT((DATE(2000, MONTH(M58), DAY(M58)) - DATE(2000, 3, 12)) / 15) + 1 -> 3
A59: f58 | B59: 1 | C59: f | D59: na | E59: 3 | F59: 58 | G59: s | H59: 32 | I59: 0.526 | J59: 2 | K59: s | L59: =J59-1 -> 1 | M59: =VLOOKUP(TRIM(A59 & ""), 'planilha crua'!$A$2:$B$10000, 2, FALSE) -> 45407 | N59: =INT((DATE(2000, MONTH(M59), DAY(M59)) - DATE(2000, 3, 12)) / 15) + 1 -> 3
A60: f60 | B60: 1 | C60: f | D60: na | E60: 3 | F60: 60 | G60: s | H60: 33 | I60: 0.589 | J60: 1 | K60: n | L60: =J60-1 -> 0 | M60: =VLOOKUP(TRIM(A60 & ""), 'planilha crua'!$A$2:$B$10000, 2, FALSE) -> 45407 | N60: =INT((DATE(2000, MONTH(M60), DAY(M60)) - DATE(2000, 3, 12)) / 15) + 1 -> 3
A61: f61 | B61: 1 | C61: f | D61: na | E61: 5 | F61: 61 | G61: a | H61: 5 | I61: 0.52 | J61: 2 | K61: s | L61: =J61-1 -> 1 | M61: =VLOOKUP(TRIM(A61 & ""), 'planilha crua'!$A$2:$B$10000, 2, FALSE) -> 45412 | N61: =INT((DATE(2000, MONTH(M61), DAY(M61)) - DATE(2000, 3, 12)) / 15) + 1 -> 4
... A65: f65 | B65: 1 | C65: f | D65: na | E65: 5 | F65: 65 | G65: a | H65: 5 | I65: 0.475 | J65: 1 | K65: n | L65: =J65-1 -> 0 | M65: =VLOOKUP(TRIM(A65 & ""), 'planilha crua'!$A$2:$B$10000, 2, FALSE) -> 45412 | N65: =INT((DATE(2000, MONTH(M65), DAY(M65)) - DATE(2000, 3, 12)) / 15) + 1 -> 4
...
